<?xml version="1.0" ?>
<!-- =================================================================================== -->
<!-- |    This document was autogenerated by xacro from robot.xacro                    | -->
<!-- |    EDITING THIS FILE BY HAND IS NOT RECOMMENDED                                 | -->
<!-- =================================================================================== -->
<robot name="quadruped_robot">
  <!-- =============== Link & Joint =============== -->
  <!-- Base -->
  <link name="trunk">
    <visual>
      <geometry>
        <mesh filename="package://robot_description/meshes/DAE/base/base_link.dae"/>
      </geometry>
    </visual>
    <collision>
      <geometry>
        <mesh filename="package://robot_description/meshes/STL/base/base_link.stl"/>
      </geometry>
    </collision>
    <inertial>
      <origin xyz="-0.1 0 0.09"/>
      <mass value="9.7"/>
      <inertia ixx="0.075" ixy="-0.0017" ixz="-0.0017" iyy="0.4" iyz="-0.0008" izz="0.43"/>
    </inertial>
  </link>
  <joint name="RL_hip_joint" type="revolute">
    <origin rpy="0 1.57079637 -1.57079637" xyz="-0.277 0.06 0.089405"/>
    <parent link="trunk"/>
    <child link="RL_hip"/>
    <limit effort="500" lower="-3.14159" upper="3.14159" velocity="10"/>
    <dynamics damping="0.005" friction="0.1"/>
    <axis xyz="0 -1 0"/>
  </joint>
  <link name="RL_hip">
    <visual>
      <geometry>
        <mesh filename="package://robot_description/meshes/DAE/leg_joint/leg_joint.dae"/>
      </geometry>
    </visual>
    <collision>
      <geometry>
        <mesh filename="package://robot_description/meshes/STL/leg_joint/leg_joint.stl"/>
      </geometry>
    </collision>
    <inertial>
      <origin xyz="0 0 -0.038"/>
      <mass value="1.16"/>
      <inertia ixx="0.002" ixy="0.0" ixz="0.0" iyy="0.002" iyz="0.0" izz="0.001"/>
    </inertial>
  </link>
  <joint name="RR_hip_joint" type="revolute">
    <origin rpy="0 -1.57079637 -1.57079637" xyz="-0.277 -0.06 0.089405"/>
    <parent link="trunk"/>
    <child link="RR_hip"/>
    <limit effort="500" lower="-3.14159" upper="3.14159" velocity="10"/>
    <dynamics damping="0.005" friction="0.1"/>
    <axis xyz="0 1 0"/>
  </joint>
  <link name="RR_hip">
    <visual>
      <geometry>
        <mesh filename="package://robot_description/meshes/DAE/leg_joint/leg_joint.dae"/>
      </geometry>
    </visual>
    <collision>
      <geometry>
        <mesh filename="package://robot_description/meshes/STL/leg_joint/leg_joint.stl"/>
      </geometry>
    </collision>
    <inertial>
      <origin xyz="0 0 -0.038"/>
      <mass value="1.16"/>
      <inertia ixx="0.002" ixy="0.0" ixz="0.0" iyy="0.002" iyz="0.0" izz="0.001"/>
    </inertial>
  </link>
  <joint name="FL_hip_joint" type="revolute">
    <origin rpy="0 1.57079637 -1.57079637" xyz="0.282 0.06 0.090255"/>
    <parent link="trunk"/>
    <child link="FL_hip"/>
    <limit effort="500" lower="-3.14159" upper="3.14159" velocity="10"/>
    <dynamics damping="0.005" friction="0.1"/>
    <axis xyz="0 -1 0"/>
  </joint>
  <link name="FL_hip">
    <visual>
      <geometry>
        <mesh filename="package://robot_description/meshes/DAE/leg_joint/leg_joint.dae"/>
      </geometry>
    </visual>
    <collision>
      <geometry>
        <mesh filename="package://robot_description/meshes/STL/leg_joint/leg_joint.stl"/>
      </geometry>
    </collision>
    <inertial>
      <origin xyz="0 0 -0.038"/>
      <mass value="1.16"/>
      <inertia ixx="0.002" ixy="0.0" ixz="0.0" iyy="0.002" iyz="0.0" izz="0.001"/>
    </inertial>
  </link>
  <joint name="FR_hip_joint" type="revolute">
    <origin rpy="0 -1.57079637 -1.57079637" xyz="0.282 -0.06 0.090255"/>
    <parent link="trunk"/>
    <child link="FR_hip"/>
    <limit effort="500" lower="-3.14159" upper="3.14159" velocity="10"/>
    <dynamics damping="0.005" friction="0.1"/>
    <axis xyz="0 1 0"/>
  </joint>
  <link name="FR_hip">
    <visual>
      <geometry>
        <mesh filename="package://robot_description/meshes/DAE/leg_joint/leg_joint.dae"/>
      </geometry>
    </visual>
    <collision>
      <geometry>
        <mesh filename="package://robot_description/meshes/STL/leg_joint/leg_joint.stl"/>
      </geometry>
    </collision>
    <inertial>
      <origin xyz="0 0 -0.038"/>
      <mass value="1.16"/>
      <inertia ixx="0.002" ixy="0.0" ixz="0.0" iyy="0.002" iyz="0.0" izz="0.001"/>
    </inertial>
  </link>
  <joint name="FL_thigh_joint" type="revolute">
    <origin rpy="1.57079637 0 0" xyz="0 0 -0.114"/>
    <parent link="FL_hip"/>
    <child link="FL_thigh"/>
    <limit effort="500" lower="-3" upper="3" velocity="10"/>
    <dynamics damping="0.005" friction="0.1"/>
    <axis xyz="0 1 0"/>
  </joint>
  <link name="FL_thigh">
    <visual>
      <geometry>
        <mesh filename="package://robot_description/meshes/DAE/left_thigh/left_thigh.dae"/>
      </geometry>
    </visual>
    <collision>
      <geometry>
        <mesh filename="package://robot_description/meshes/STL/left_thigh/left_thigh.stl"/>
      </geometry>
    </collision>
    <inertial>
      <origin xyz="0.17 -0.028 0.014"/>
      <mass value="1.24"/>
      <inertia ixx="0.002" ixy="0" ixz="0" iyy="0.002" iyz="0" izz="0.001"/>
      <!-- inertia ixx="-0.5" ixy="0.003" ixz="0.145" iyy="-0.496" iyz="-0.0096" izz="0.012" -->
    </inertial>
  </link>
  <joint name="RL_thigh_joint" type="revolute">
    <origin rpy="1.57079637 0 0" xyz="0 0 -0.114"/>
    <parent link="RL_hip"/>
    <child link="RL_thigh"/>
    <limit effort="500" lower="-3" upper="3" velocity="10"/>
    <dynamics damping="0.005" friction="0.1"/>
    <axis xyz="0 1 0"/>
  </joint>
  <link name="RL_thigh">
    <visual>
      <geometry>
        <mesh filename="package://robot_description/meshes/DAE/left_thigh/left_thigh.dae"/>
      </geometry>
    </visual>
    <collision>
      <geometry>
        <mesh filename="package://robot_description/meshes/STL/left_thigh/left_thigh.stl"/>
      </geometry>
    </collision>
    <inertial>
      <origin xyz="0.17 -0.028 0.014"/>
      <mass value="1.24"/>
      <inertia ixx="0.002" ixy="0" ixz="0" iyy="0.002" iyz="0" izz="0.001"/>
      <!-- inertia ixx="-0.5" ixy="0.003" ixz="0.145" iyy="-0.496" iyz="-0.0096" izz="0.012" -->
    </inertial>
  </link>
  <joint name="FR_thigh_joint" type="revolute">
    <origin rpy="1.57079637 0 3.14159274" xyz="0 0 -0.114"/>
    <parent link="FR_hip"/>
    <child link="FR_thigh"/>
    <limit effort="500" lower="-3" upper="3" velocity="10"/>
    <dynamics damping="0.005" friction="0.1"/>
    <axis xyz="0 -1 0"/>
  </joint>
  <link name="FR_thigh">
    <visual>
      <geometry>
        <mesh filename="package://robot_description/meshes/DAE/right_thigh/right_thigh.dae"/>
      </geometry>
    </visual>
    <collision>
      <geometry>
        <mesh filename="package://robot_description/meshes/STL/right_thigh/right_thigh.stl"/>
      </geometry>
    </collision>
    <inertial>
      <origin xyz="0.17 -0.028 -0.014"/>
      <mass value="1.24"/>
      <inertia ixx="0.002" ixy="0.0" ixz="0.0" iyy="0.002" iyz="0.0" izz="0.001"/>
      <!--inertia ixx="-0.44" ixy="0.012" ixz="0.14" iyy="-0.423" iyz="0.0217" izz="0.0135" -->
    </inertial>
  </link>
  <joint name="RR_thigh_joint" type="revolute">
    <origin rpy="1.57079637 0 3.14159274" xyz="0 0 -0.114"/>
    <parent link="RR_hip"/>
    <child link="RR_thigh"/>
    <limit effort="500" lower="-3" upper="3" velocity="10"/>
    <dynamics damping="0.005" friction="0.1"/>
    <axis xyz="0 -1 0"/>
  </joint>
  <link name="RR_thigh">
    <visual>
      <geometry>
        <mesh filename="package://robot_description/meshes/DAE/right_thigh/right_thigh.dae"/>
      </geometry>
    </visual>
    <collision>
      <geometry>
        <mesh filename="package://robot_description/meshes/STL/right_thigh/right_thigh.stl"/>
      </geometry>
    </collision>
    <inertial>
      <origin xyz="0.17 -0.028 -0.014"/>
      <mass value="1.24"/>
      <inertia ixx="0.002" ixy="0.0" ixz="0.0" iyy="0.002" iyz="0.0" izz="0.001"/>
      <!--inertia ixx="-0.44" ixy="0.012" ixz="0.14" iyy="-0.423" iyz="0.0217" izz="0.0135" -->
    </inertial>
  </link>
  <joint name="FL_calf_joint" type="revolute">
    <origin rpy="0 3.14159274 0" xyz="0.426 -0.0285 0"/>
    <parent link="FL_thigh"/>
    <child link="FL_calf"/>
    <limit effort="500" lower="-3.14159" upper="3.14159" velocity="10"/>
    <dynamics damping="0.005" friction="0.1"/>
    <axis xyz="0 1 0"/>
  </joint>
  <link name="FL_calf">
    <visual>
      <geometry>
        <mesh filename="package://robot_description/meshes/DAE/shin/shin.dae"/>
      </geometry>
    </visual>
    <collision>
      <geometry>
        <mesh filename="package://robot_description/meshes/STL/shin/shin.stl"/>
      </geometry>
    </collision>
    <inertial>
      <origin xyz="-0.158 0.011 0.0"/>
      <mass value="0.66"/>
      <inertia ixx="0.0003" ixy="0.0013" ixz="0.000045" iyy="0.029" iyz="-0.000003" izz="0.029"/>
    </inertial>
  </link>
  <joint name="RL_calf_joint" type="revolute">
    <origin rpy="0 3.14159274 0" xyz="0.426 -0.0285 0"/>
    <parent link="RL_thigh"/>
    <child link="RL_calf"/>
    <limit effort="500" lower="-3.14159" upper="3.14159" velocity="10"/>
    <dynamics damping="0.005" friction="0.1"/>
    <axis xyz="0 1 0"/>
  </joint>
  <link name="RL_calf">
    <visual>
      <geometry>
        <mesh filename="package://robot_description/meshes/DAE/shin/shin.dae"/>
      </geometry>
    </visual>
    <collision>
      <geometry>
        <mesh filename="package://robot_description/meshes/STL/shin/shin.stl"/>
      </geometry>
    </collision>
    <inertial>
      <origin xyz="-0.158 0.011 0.0"/>
      <mass value="0.66"/>
      <inertia ixx="0.0003" ixy="0.0013" ixz="0.000045" iyy="0.029" iyz="-0.000003" izz="0.029"/>
    </inertial>
  </link>
  <joint name="FR_calf_joint" type="revolute">
    <origin rpy="3.14159274 3.14159274 0" xyz="0.426 -0.0285 0"/>
    <parent link="FR_thigh"/>
    <child link="FR_calf"/>
    <limit effort="500" lower="-3.14159" upper="3.14159" velocity="10"/>
    <dynamics damping="0.005" friction="0.1"/>
    <axis xyz="0 1 0"/>
  </joint>
  <link name="FR_calf">
    <visual>
      <geometry>
        <mesh filename="package://robot_description/meshes/DAE/shin/shin.dae"/>
      </geometry>
    </visual>
    <collision>
      <geometry>
        <mesh filename="package://robot_description/meshes/STL/shin/shin.stl"/>
      </geometry>
    </collision>
    <inertial>
      <origin xyz="-0.158 0.011 0.0"/>
      <mass value="0.66"/>
      <inertia ixx="0.0003" ixy="0.0013" ixz="0.000045" iyy="0.029" iyz="-0.000003" izz="0.029"/>
    </inertial>
  </link>
  <joint name="RR_calf_joint" type="revolute">
    <origin rpy="3.14159274 3.14159274 0" xyz="0.426 -0.0285 0"/>
    <parent link="RR_thigh"/>
    <child link="RR_calf"/>
    <limit effort="500" lower="-3.14159" upper="3.14159" velocity="10"/>
    <dynamics damping="0.005" friction="0.1"/>
    <axis xyz="0 1 0"/>
  </joint>
  <link name="RR_calf">
    <visual>
      <geometry>
        <mesh filename="package://robot_description/meshes/DAE/shin/shin.dae"/>
      </geometry>
    </visual>
    <collision>
      <geometry>
        <mesh filename="package://robot_description/meshes/STL/shin/shin.stl"/>
      </geometry>
    </collision>
    <inertial>
      <origin xyz="-0.158 0.011 0.0"/>
      <mass value="0.66"/>
      <inertia ixx="0.0003" ixy="0.0013" ixz="0.000045" iyy="0.029" iyz="-0.000003" izz="0.029"/>
    </inertial>
  </link>
  <joint name="FL_foot_fixed" type="fixed">
    <origin rpy="0 0 0" xyz="-0.345 0 0"/>
    <parent link="FL_calf"/>
    <child link="FL_foot"/>
  </joint>
  <link name="FL_foot">
    <visual>
      <geometry>
        <mesh filename="package://robot_description/meshes/DAE/foot/foot.dae"/>
      </geometry>
    </visual>
    <collision>
      <geometry>
        <mesh filename="package://robot_description/meshes/STL/foot/foot.stl"/>
      </geometry>
    </collision>
    <inertial>
      <origin xyz="0.0 0.0 0.0"/>
      <mass value="0.015"/>
      <inertia ixx="0.000001349" ixy="0.0" ixz="0.0" iyy="0.000001349" iyz="0.0" izz="0.000001349"/>
    </inertial>
  </link>
  <joint name="RL_foot_fixed" type="fixed">
    <origin rpy="0 0 0" xyz="-0.345 0 0"/>
    <parent link="RL_calf"/>
    <child link="RL_foot"/>
  </joint>
  <link name="RL_foot">
    <visual>
      <geometry>
        <mesh filename="package://robot_description/meshes/DAE/foot/foot.dae"/>
      </geometry>
    </visual>
    <collision>
      <geometry>
        <mesh filename="package://robot_description/meshes/STL/foot/foot.stl"/>
      </geometry>
    </collision>
    <inertial>
      <origin xyz="0.0 0.0 0.0"/>
      <mass value="0.015"/>
      <inertia ixx="0.000001349" ixy="0.0" ixz="0.0" iyy="0.000001349" iyz="0.0" izz="0.000001349"/>
    </inertial>
  </link>
  <joint name="FR_foot_fixed" type="fixed">
    <origin rpy="0 0 0" xyz="-0.345 0 0"/>
    <parent link="FR_calf"/>
    <child link="FR_foot"/>
  </joint>
  <link name="FR_foot">
    <visual>
      <geometry>
        <mesh filename="package://robot_description/meshes/DAE/foot/foot.dae"/>
      </geometry>
    </visual>
    <collision>
      <geometry>
        <mesh filename="package://robot_description/meshes/STL/foot/foot.stl"/>
      </geometry>
    </collision>
    <inertial>
      <origin xyz="0.0 0.0 0.0"/>
      <mass value="0.015"/>
      <inertia ixx="0.000001349" ixy="0.0" ixz="0.0" iyy="0.000001349" iyz="0.0" izz="0.000001349"/>
    </inertial>
  </link>
  <joint name="RR_foot_fixed" type="fixed">
    <origin rpy="0 0 0" xyz="-0.345 0 0"/>
    <parent link="RR_calf"/>
    <child link="RR_foot"/>
  </joint>
  <link name="RR_foot">
    <visual>
      <geometry>
        <mesh filename="package://robot_description/meshes/DAE/foot/foot.dae"/>
      </geometry>
    </visual>
    <collision>
      <geometry>
        <mesh filename="package://robot_description/meshes/STL/foot/foot.stl"/>
      </geometry>
    </collision>
    <inertial>
      <origin xyz="0.0 0.0 0.0"/>
      <mass value="0.015"/>
      <inertia ixx="0.000001349" ixy="0.0" ixz="0.0" iyy="0.000001349" iyz="0.0" izz="0.000001349"/>
    </inertial>
  </link>
</robot>
